import java_two.Person;

import java.io.IOException;

public class Exceptions {
    public static void main(String[] args) {
//        int [] array = new int[10];

//        try {
//            System.out.println(array[11]);
//        }catch (ArrayIndexOutOfBoundsException e) {
//            //code that handles this exception
//            System.out.println("Not a valid index");
//
//            System.out.println(e.getMessage());
//            //prints out what went wrong
//            e.printStackTrace();
//            //gives the console output of what is wrong and where
//        }finally {
//            System.out.println("Finally called");
//        }
//        int a = 0;
//        try {
//            throw new IOException("Matt's exception");
//        }catch (RuntimeException|IOException e) {
//             a = 5;
//            System.out.println("An exception was caught");
//        }
//        //a cannot be seen here
//        System.out.println(a);

        System.out.println("Done");
    }
}

